Traceback (most recent call last):
  File "/usr/bin/daphne", line 33, in <module>
    sys.exit(load_entry_point('daphne==3.0.2', 'console_scripts', 'daphne')())
  File "/usr/lib/python3/dist-packages/daphne/cli.py", line 170, in entrypoint
    cls().run(sys.argv[1:])
  File "/usr/lib/python3/dist-packages/daphne/cli.py", line 232, in run
    application = import_by_path(args.application)
  File "/usr/lib/python3/dist-packages/daphne/utils.py", line 12, in import_by_path
    target = importlib.import_module(module_path)
  File "/usr/lib/python3.10/importlib/__init__.py", line 126, in import_module
    return _bootstrap._gcd_import(name[level:], package, level)
  File "<frozen importlib._bootstrap>", line 1050, in _gcd_import
  File "<frozen importlib._bootstrap>", line 1027, in _find_and_load
  File "<frozen importlib._bootstrap>", line 1004, in _find_and_load_unlocked
ModuleNotFoundError: No module named 'asgi'
Error in sys.excepthook:
Traceback (most recent call last):
  File "/usr/lib/python3/dist-packages/apport_python_hook.py", line 153, in apport_excepthook
    with os.fdopen(os.open(pr_filename,
FileNotFoundError: [Errno 2] No such file or directory: '/var/crash/_usr_bin_daphne.1000.crash'

Original exception was:
Traceback (most recent call last):
  File "/usr/bin/daphne", line 33, in <module>
    sys.exit(load_entry_point('daphne==3.0.2', 'console_scripts', 'daphne')())
  File "/usr/lib/python3/dist-packages/daphne/cli.py", line 170, in entrypoint
    cls().run(sys.argv[1:])
  File "/usr/lib/python3/dist-packages/daphne/cli.py", line 232, in run
    application = import_by_path(args.application)
  File "/usr/lib/python3/dist-packages/daphne/utils.py", line 12, in import_by_path
    target = importlib.import_module(module_path)
  File "/usr/lib/python3.10/importlib/__init__.py", line 126, in import_module
    return _bootstrap._gcd_import(name[level:], package, level)
  File "<frozen importlib._bootstrap>", line 1050, in _gcd_import
  File "<frozen importlib._bootstrap>", line 1027, in _find_and_load
  File "<frozen importlib._bootstrap>", line 1004, in _find_and_load_unlocked
ModuleNotFoundError: No module named 'asgi'
usage: manage.py runworker [-h] [--layer LAYER] [--version] [-v {0,1,2,3}]
                           [--settings SETTINGS] [--pythonpath PYTHONPATH]
                           [--traceback] [--no-color] [--force-color]
                           [--skip-checks]
                           channels [channels ...]
manage.py runworker: error: the following arguments are required: channels
Traceback (most recent call last):
  File "/usr/bin/daphne", line 33, in <module>
    sys.exit(load_entry_point('daphne==3.0.2', 'console_scripts', 'daphne')())
  File "/usr/lib/python3/dist-packages/daphne/cli.py", line 170, in entrypoint
    cls().run(sys.argv[1:])
  File "/usr/lib/python3/dist-packages/daphne/cli.py", line 232, in run
    application = import_by_path(args.application)
  File "/usr/lib/python3/dist-packages/daphne/utils.py", line 12, in import_by_path
    target = importlib.import_module(module_path)
  File "/usr/lib/python3.10/importlib/__init__.py", line 126, in import_module
    return _bootstrap._gcd_import(name[level:], package, level)
  File "<frozen importlib._bootstrap>", line 1050, in _gcd_import
  File "<frozen importlib._bootstrap>", line 1027, in _find_and_load
  File "<frozen importlib._bootstrap>", line 1004, in _find_and_load_unlocked
ModuleNotFoundError: No module named 'asgi'
Error in sys.excepthook:
Traceback (most recent call last):
  File "/usr/lib/python3/dist-packages/apport_python_hook.py", line 153, in apport_excepthook
    with os.fdopen(os.open(pr_filename,
FileNotFoundError: [Errno 2] No such file or directory: '/var/crash/_usr_bin_daphne.1000.crash'

Original exception was:
Traceback (most recent call last):
  File "/usr/bin/daphne", line 33, in <module>
    sys.exit(load_entry_point('daphne==3.0.2', 'console_scripts', 'daphne')())
  File "/usr/lib/python3/dist-packages/daphne/cli.py", line 170, in entrypoint
    cls().run(sys.argv[1:])
  File "/usr/lib/python3/dist-packages/daphne/cli.py", line 232, in run
    application = import_by_path(args.application)
  File "/usr/lib/python3/dist-packages/daphne/utils.py", line 12, in import_by_path
    target = importlib.import_module(module_path)
  File "/usr/lib/python3.10/importlib/__init__.py", line 126, in import_module
    return _bootstrap._gcd_import(name[level:], package, level)
  File "<frozen importlib._bootstrap>", line 1050, in _gcd_import
  File "<frozen importlib._bootstrap>", line 1027, in _find_and_load
  File "<frozen importlib._bootstrap>", line 1004, in _find_and_load_unlocked
ModuleNotFoundError: No module named 'asgi'
